<?xml version="1.0"?>
<robot xmlns:xacro="http://www.ros.org/wiki/xacro">

    <xacro:include filename="inertial_macros.xacro"/>

    <material name="white">
        <color rgba="1 1 1 1" />
    </material>

    <material name="orange">
        <color rgba="1 0.3 0.1 1"/>
    </material>

    <material name="blue">
        <color rgba="0.2 0.2 1 1"/>
    </material>

    <material name="black">
        <color rgba="0 0 0 1"/>
    </material>

    <!-- BASE LINK -->

    <link name="base_link">

    </link>

    <!-- CHASSIS LINK -->

    <joint name="chassis_joint" type="fixed">
        <parent link="base_link"/>
        <child link="chassis"/>
        <origin xyz="-0.1 0 0"/>
    </joint>

    <link name="chassis">
        <visual>
            <origin xyz="0.2 0 0.03"/>
            <geometry>
                <box size="0.4 0.18 0.06"/>
            </geometry>
            <material name="white"/>
        </visual>
        <collision>
            <origin xyz="0.2 0 0.03"/>
            <geometry>
                <box size="0.4 0.18 0.06"/>
            </geometry>
        </collision>
        <xacro:inertial_box mass="0.5" x="0.4" y="0.18" z="0.06">
            <origin xyz="0.2 0 0.03" rpy="0 0 0"/>
        </xacro:inertial_box>
    </link>

    <gazebo reference="chassis">
        <material>Gazebo/White</material>
    </gazebo>
    
    <!-- BACK RIGHT WHEEL LINK -->

    <joint name="back_right_wheel_joint" type="continuous">
        <parent link="base_link"/>
        <child link="back_right_wheel"/>
        <origin xyz="-0.075 -0.1225 0.03" rpy="${pi/2} 0 0" />
        <axis xyz="0 0 -1"/>
    </joint>

    <link name="back_right_wheel">
        <visual>
            <geometry>
                <cylinder radius="0.0675" length="0.065"/>
            </geometry>
            <material name="blue"/>
        </visual>
        <collision>
            <geometry>
                <cylinder radius="0.0675" length="0.065"/>
            </geometry>
        </collision>
        <xacro:inertial_cylinder mass="0.1" length="0.065" radius="0.0675">
            <origin xyz="0 0 0" rpy="0 0 0"/>
        </xacro:inertial_cylinder>
    </link>

    <gazebo reference="back_right_wheel">
        <material>Gazebo/Blue</material>
    </gazebo>

    <!-- BACK LEFT WHEEL LINK -->

    <joint name="back_left_wheel_joint" type="continuous">
        <parent link="base_link"/>
        <child link="back_left_wheel"/>
        <origin xyz="-0.075 0.1225 0.03" rpy="-${pi/2} 0 0" />
        <axis xyz="0 0 1"/>
    </joint>

    <link name="back_left_wheel">
        <visual>
            <geometry>
                <cylinder radius="0.0675" length="0.065"/>
            </geometry>
            <material name="blue"/>
        </visual>
        <collision>
            <geometry>
                <cylinder radius="0.0675" length="0.065"/>
            </geometry>
        </collision>
        <xacro:inertial_cylinder mass="0.1" length="0.065" radius="0.0675">
            <origin xyz="0 0 0" rpy="0 0 0"/>
        </xacro:inertial_cylinder>
    </link>

    <gazebo reference="back_left_wheel">
        <material>Gazebo/Blue</material>
    </gazebo>
    
    <!-- FRONT RIGHT WHEEL LINK -->

    <joint name="front_right_wheel_joint" type="fixed">
        <parent link="base_link"/>
        <child link="front_right_wheel"/>
        <origin xyz="0.275 0.1225 0.03" rpy="-${pi/2} 0 0" />
        <axis xyz="0 0 1"/>
    </joint>

    <link name="front_right_wheel">
        <visual>
            <geometry>
                <cylinder radius="0.0675" length="0.065"/>
            </geometry>
            <material name="blue"/>
        </visual>
        <collision>
            <geometry>
                <cylinder radius="0.0675" length="0.065"/>
            </geometry>
        </collision>
        <xacro:inertial_cylinder mass="0.1" length="0.065" radius="0.0675">
            <origin xyz="0 0 0" rpy="0 0 0"/>
        </xacro:inertial_cylinder>
    </link>

    <gazebo reference="front_right_wheel">
        <material>Gazebo/Blue</material>
        <mu1 value="0.001"/>
        <mu2 value="0.001"/>
    </gazebo>
    
    <!-- FRONT LEFT WHEEL LINK -->

    <joint name="front_left_wheel_joint" type="fixed">
        <parent link="base_link"/>
        <child link="front_left_wheel"/>
        <origin xyz="0.275 -0.1225 0.03" rpy="${pi/2} 0 0" />
        <axis xyz="0 0 -1"/>
    </joint>

    <link name="front_left_wheel">
        <visual>
            <geometry>
                <cylinder radius="0.0675" length="0.065"/>
            </geometry>
            <material name="blue"/>
        </visual>
        <collision>
            <geometry>
                <cylinder radius="0.0675" length="0.065"/>
            </geometry>
        </collision>
        <xacro:inertial_cylinder mass="0.1" length="0.065" radius="0.0675">
            <origin xyz="0 0 0" rpy="0 0 0"/>
        </xacro:inertial_cylinder>
    </link>

    <gazebo reference="front_left_wheel">
        <material>Gazebo/Blue</material>
        <mu1 value="0.001"/>
        <mu2 value="0.001"/>
    </gazebo>
    
</robot>